<?xml version="1.0"?>
<robot xmlns:xacro="http://www.ros.org/wiki/xacro" name="so100">

  <!-- Arguments -->
  <xacro:arg name="arm_side" default="both"/>
  <xacro:property name="arm_side" value="$(arg arm_side)"/>
  
  <!-- Common properties -->
  <xacro:property name="pi" value="3.14159265359"/>
  
  <!-- Include SO-100 arm macros -->
  <xacro:macro name="so100_arm" params="prefix parent_link *origin">
    
    <!-- Base link -->
    <link name="${prefix}_base_link">
      <visual>
        <geometry>
          <cylinder length="0.05" radius="0.05"/>
        </geometry>
        <material name="grey">
          <color rgba="0.5 0.5 0.5 1.0"/>
        </material>
      </visual>
      <collision>
        <geometry>
          <cylinder length="0.05" radius="0.05"/>
        </geometry>
      </collision>
      <inertial>
        <mass value="0.5"/>
        <inertia ixx="0.001" ixy="0.0" ixz="0.0" iyy="0.001" iyz="0.0" izz="0.001"/>
      </inertial>
    </link>
    
    <!-- Connect to parent link -->
    <joint name="${prefix}_base_joint" type="fixed">
      <xacro:insert_block name="origin"/>
      <parent link="${parent_link}"/>
      <child link="${prefix}_base_link"/>
    </joint>
    
    <!-- Shoulder pan joint -->
    <joint name="${prefix}_shoulder_pan_joint" type="revolute">
      <parent link="${prefix}_base_link"/>
      <child link="${prefix}_shoulder_link"/>
      <origin xyz="0 0 0.05" rpy="0 0 0"/>
      <axis xyz="0 0 1"/>
      <limit lower="${-pi}" upper="${pi}" effort="100" velocity="1.0"/>
    </joint>
    
    <!-- Shoulder link -->
    <link name="${prefix}_shoulder_link">
      <visual>
        <geometry>
          <box size="0.1 0.1 0.1"/>
        </geometry>
        <material name="blue">
          <color rgba="0.0 0.0 0.8 1.0"/>
        </material>
      </visual>
      <collision>
        <geometry>
          <box size="0.1 0.1 0.1"/>
        </geometry>
      </collision>
      <inertial>
        <mass value="0.5"/>
        <inertia ixx="0.001" ixy="0.0" ixz="0.0" iyy="0.001" iyz="0.0" izz="0.001"/>
      </inertial>
    </link>
    
    <!-- Shoulder lift joint -->
    <joint name="${prefix}_shoulder_lift_joint" type="revolute">
      <parent link="${prefix}_shoulder_link"/>
      <child link="${prefix}_upper_arm_link"/>
      <origin xyz="0 0 0.1" rpy="0 0 0"/>
      <axis xyz="0 1 0"/>
      <limit lower="${-pi/2}" upper="${pi/2}" effort="100" velocity="1.0"/>
    </joint>
    
    <!-- Upper arm link -->
    <link name="${prefix}_upper_arm_link">
      <visual>
        <geometry>
          <cylinder length="0.2" radius="0.03"/>
        </geometry>
        <origin xyz="0 0 0.1" rpy="0 0 0"/>
        <material name="red">
          <color rgba="0.8 0.0 0.0 1.0"/>
        </material>
      </visual>
      <collision>
        <geometry>
          <cylinder length="0.2" radius="0.03"/>
        </geometry>
        <origin xyz="0 0 0.1" rpy="0 0 0"/>
      </collision>
      <inertial>
        <mass value="0.5"/>
        <inertia ixx="0.001" ixy="0.0" ixz="0.0" iyy="0.001" iyz="0.0" izz="0.001"/>
      </inertial>
    </link>
    
    <!-- Elbow joint -->
    <joint name="${prefix}_elbow_flex_joint" type="revolute">
      <parent link="${prefix}_upper_arm_link"/>
      <child link="${prefix}_forearm_link"/>
      <origin xyz="0 0 0.2" rpy="0 0 0"/>
      <axis xyz="0 1 0"/>
      <limit lower="${-pi}" upper="${pi}" effort="100" velocity="1.0"/>
    </joint>
    
    <!-- Forearm link -->
    <link name="${prefix}_forearm_link">
      <visual>
        <geometry>
          <cylinder length="0.2" radius="0.02"/>
        </geometry>
        <origin xyz="0 0 0.1" rpy="0 0 0"/>
        <material name="green">
          <color rgba="0.0 0.8 0.0 1.0"/>
        </material>
      </visual>
      <collision>
        <geometry>
          <cylinder length="0.2" radius="0.02"/>
        </geometry>
        <origin xyz="0 0 0.1" rpy="0 0 0"/>
      </collision>
      <inertial>
        <mass value="0.5"/>
        <inertia ixx="0.001" ixy="0.0" ixz="0.0" iyy="0.001" iyz="0.0" izz="0.001"/>
      </inertial>
    </link>
    
    <!-- Wrist flex joint -->
    <joint name="${prefix}_wrist_flex_joint" type="revolute">
      <parent link="${prefix}_forearm_link"/>
      <child link="${prefix}_wrist_link"/>
      <origin xyz="0 0 0.2" rpy="0 0 0"/>
      <axis xyz="0 1 0"/>
      <limit lower="${-pi/2}" upper="${pi/2}" effort="100" velocity="1.0"/>
    </joint>
    
    <!-- Wrist link -->
    <link name="${prefix}_wrist_link">
      <visual>
        <geometry>
          <box size="0.05 0.05 0.05"/>
        </geometry>
        <material name="orange">
          <color rgba="1.0 0.5 0.0 1.0"/>
        </material>
      </visual>
      <collision>
        <geometry>
          <box size="0.05 0.05 0.05"/>
        </geometry>
      </collision>
      <inertial>
        <mass value="0.1"/>
        <inertia ixx="0.001" ixy="0.0" ixz="0.0" iyy="0.001" iyz="0.0" izz="0.001"/>
      </inertial>
    </link>
    
    <!-- Wrist roll joint -->
    <joint name="${prefix}_wrist_roll_joint" type="revolute">
      <parent link="${prefix}_wrist_link"/>
      <child link="${prefix}_hand_link"/>
      <origin xyz="0 0 0.05" rpy="0 0 0"/>
      <axis xyz="0 0 1"/>
      <limit lower="${-pi}" upper="${pi}" effort="100" velocity="1.0"/>
    </joint>
    
    <!-- Hand link -->
    <link name="${prefix}_hand_link">
      <visual>
        <geometry>
          <box size="0.05 0.08 0.02"/>
        </geometry>
        <material name="grey">
          <color rgba="0.5 0.5 0.5 1.0"/>
        </material>
      </visual>
      <collision>
        <geometry>
          <box size="0.05 0.08 0.02"/>
        </geometry>
      </collision>
      <inertial>
        <mass value="0.1"/>
        <inertia ixx="0.001" ixy="0.0" ixz="0.0" iyy="0.001" iyz="0.0" izz="0.001"/>
      </inertial>
    </link>
    
    <!-- Gripper joint -->
    <joint name="${prefix}_gripper_joint" type="prismatic">
      <parent link="${prefix}_hand_link"/>
      <child link="${prefix}_gripper_link"/>
      <origin xyz="0 0 0.01" rpy="0 0 0"/>
      <axis xyz="0 1 0"/>
      <limit lower="0.0" upper="0.04" effort="100" velocity="1.0"/>
    </joint>
    
    <!-- Gripper link -->
    <link name="${prefix}_gripper_link">
      <visual>
        <geometry>
          <box size="0.02 0.08 0.02"/>
        </geometry>
        <material name="white">
          <color rgba="1.0 1.0 1.0 1.0"/>
        </material>
      </visual>
      <collision>
        <geometry>
          <box size="0.02 0.08 0.02"/>
        </geometry>
      </collision>
      <inertial>
        <mass value="0.1"/>
        <inertia ixx="0.001" ixy="0.0" ixz="0.0" iyy="0.001" iyz="0.0" izz="0.001"/>
      </inertial>
    </link>
    
    <!-- ROS2 Control -->
    <ros2_control name="${prefix}_arm_controller" type="system">
      <hardware>
        <plugin>arm_control/WaveshareHardwareInterface</plugin>
        <param name="port">${prefix == 'left' ? '/dev/ttyUSB0' : '/dev/ttyUSB1'}</param>
        <param name="baudrate">1000000</param>
      </hardware>
      <joint name="${prefix}_shoulder_pan_joint">
        <command_interface name="position"/>
        <state_interface name="position"/>
        <state_interface name="velocity"/>
        <state_interface name="effort"/>
        <param name="id">1</param>
        <param name="model">sts3215</param>
      </joint>
      <joint name="${prefix}_shoulder_lift_joint">
        <command_interface name="position"/>
        <state_interface name="position"/>
        <state_interface name="velocity"/>
        <state_interface name="effort"/>
        <param name="id">2</param>
        <param name="model">sts3215</param>
      </joint>
      <joint name="${prefix}_elbow_flex_joint">
        <command_interface name="position"/>
        <state_interface name="position"/>
        <state_interface name="velocity"/>
        <state_interface name="effort"/>
        <param name="id">3</param>
        <param name="model">sts3215</param>
      </joint>
      <joint name="${prefix}_wrist_flex_joint">
        <command_interface name="position"/>
        <state_interface name="position"/>
        <state_interface name="velocity"/>
        <state_interface name="effort"/>
        <param name="id">4</param>
        <param name="model">sts3215</param>
      </joint>
      <joint name="${prefix}_wrist_roll_joint">
        <command_interface name="position"/>
        <state_interface name="position"/>
        <state_interface name="velocity"/>
        <state_interface name="effort"/>
        <param name="id">5</param>
        <param name="model">sts3215</param>
      </joint>
      <joint name="${prefix}_gripper_joint">
        <command_interface name="position"/>
        <state_interface name="position"/>
        <state_interface name="velocity"/>
        <state_interface name="effort"/>
        <param name="id">6</param>
        <param name="model">sts3215</param>
      </joint>
    </ros2_control>
  </xacro:macro>
  
  <!-- World link -->
  <link name="world"/>
  
  <!-- Include arms based on arm_side argument -->
  <xacro:if value="${arm_side == 'left' or arm_side == 'both'}">
    <xacro:so100_arm prefix="left" parent_link="world">
      <origin xyz="0 0.2 0" rpy="0 0 0"/>
    </xacro:so100_arm>
  </xacro:if>
  
  <xacro:if value="${arm_side == 'right' or arm_side == 'both'}">
    <xacro:so100_arm prefix="right" parent_link="world">
      <origin xyz="0 -0.2 0" rpy="0 0 0"/>
    </xacro:so100_arm>
  </xacro:if>
  
</robot>
